Workbook

Sheet Project Overview
A1: INVENTORY TRACKING & RECORD VERIFICATION PORTFOLIO PROJECT
A3: Project Purpose & Objectives
A4: This self-initiated portfolio project demonstrates practical skills in inventory data entry, record verification, spreadsheet organization, and data quality checking using Microsoft Excel. It involves reviewing raw inventory records, identifying duplicate entries and missing information, comparing recorded quantities with physical counts, and documenting discrepancies for follow-up.
A5: The project demonstrates attention to detail, record accuracy, organized documentation, and basic inventory-control practices relevant to entry-level Data Entry Virtual Assistant roles.
A7: Tools & Techniques Demonstrated
A8: • Data Standardization: Applying consistent product IDs, proper capitalization, trimmed spacing, and standardized date formats (YYYY-MM-DD).
A9: • Inventory Record Reconciliation: Comparing system recorded quantities against physical stock counts to identify operational variances.
A10: • Discrepancy & Value Analysis: Utilizing mathematical formulas (Variance, Absolute Variance, and Estimated Discrepancy Value in PHP).
A11: • Error Auditing & Logging: Systematic tracking of data-entry anomalies, missing categories/suppliers, and duplicate resolutions.
A12: • Excel Functions & Features: Dynamic formulas (COUNTA, SUM, ABS, IF), data validation, conditional formatting, Excel Tables, and freeze panes.
A14: Inventory Verification Methodology
A15: 1. Ingestion & Audit: Ingested 40 raw inventory records containing intentional data-entry inconsistencies (spacing, case, missing info, duplicates).
... A21: Summary of Results (Calculated via Workbook Formulas)
A22: Metric Description | B22: Count / Value | C22: Workbook Formula / Note
A23: Total Raw Inventory Records Reviewed | B23: =COUNTA('Raw Inventory Records'!A2:A41) | C23: Total rows in raw dataset
A24: Duplicate Records Identified and Resolved | B24: 3 | C24: INV-1011, INV-1025, INV-1038 (Merged/Removed)
A25: Unique Inventory Items Retained | B25: =COUNTA('Verified Inventory'!A2:A38) | C25: Master verified inventory count (37 unique items)
A26: Records with Quantity Discrepancies | B26: =COUNTIF('Verified Inventory'!N2:N38, "*Discrepancy*") | C26: Items with system vs physical count variance
A27: Records with Missing Information | B27: 4 | C27: INV-1006, INV-1014, INV-1022, INV-1031 (Suppliers/Categories)
A28: Items at or Below Reorder Level | B28: =COUNTIF('Verified Inventory'!M2:M38, "Low Stock*") + COUNTIF('Verified Inventory'!M2:M38, "*Low Stock*") | C28: Items requiring replenishment
A29: Total Estimated Value of Quantity Discrepancies | B29: =SUM('Verified Inventory'!L2:L38) | C29: Sum of absolute variance value (PHP)
A31: Portfolio Note
A32: Portfolio Note: All product names, supplier names, quantities, and other inventory details in this workbook are fictional and created solely for portfolio demonstration purposes.

Sheet Raw Inventory Records
A1: Record ID | B1: Product ID | C1: Product Name | D1: Category | E1: Supplier | F1: Date Recorded | G1: Quantity in System | H1: Physical Count | I1: Unit Cost (PHP) | J1: Reorder Level | K1: Remarks
A2: INV-1001 | B2: PROD-001 | C2: Wireless Mouse | D2: Peripherals | E2: TechGlobal Inc. | F2: 2026-01-10 | G2: 120 | H2: 118 | I2: 450 | J2: 25 | K2: Slight discrepancy (-2)
A3: INV-1002 | B3: PROD-002 | C3: Mechanical Keyboard | D3: Peripherals | E3: TechGlobal Inc. | F3: 2026-01-12 | G3: 75 | H3: 75 | I3: 1850 | J3: 15 | K3: Counts match
A4: INV-1003 | B4: PROD-003 | C4: 27-inch IPS Monitor | D4: Displays | E4: Apex Electronics | F4: 01/15/2026 | G4: 40 | H4: 38 | I4: 8500 | J4: 10 | K4: Discrepancy found (-2)
A5: INV-1004 | B5: prod-004 | C5: USB-C Hub | D5: Accessories | E5: DataLink Corp. | F5: 2026.01.18 | G5: 150 | H5: 150 | I5: 650 | J5: 30 | K5: Lowercase product ID, trailing spaces
A6: INV-1005 | B6: PROD-005 | C6: LAPTOP STAND | D6: Accessories | E6: DataLink Corp. | F6: 2026-01-20 | G6: 60 | H6: 55 | I6: 950 | J6: 20 | K6: All caps name, discrepancy (-5)
A7: INV-1006 | B7: PROD-006 | C7: External SSD 1TB | D7: Storage | F7: 2026-01-22 | G7: 30 | H7: 30 | I7: 4200 | J7: 10 | K7: Missing supplier
A8: INV-1007 | B8: PROD-007 | C8: HD Webcam 1080p | D8: Peripherals | E8: VisionTech | F8: 01/25/2026 | G8: 85 | H8: 80 | I8: 1200 | J8: 20 | K8: Discrepancy (-5)
A9: INV-1008 | B9: PROD-008 | C9: Bluetooth Speaker | D9: Audio | E9: SoundWave Ph | F9: 2026.01.28 | G9: 50 | H9: 50 | I9: 1500 | J9: 15 | K9: Counts match
A10: INV-1009 | B10: PROD-009 | C10: Ergonomic Office Chair | D10: Furniture | E10: ComfortSeating | F10: 2026-02-01 | G10: 20 | H10: 18 | I10: 5400 | J10: 5 | K10: Discrepancy (-2)
A11: INV-1010 | B11: PROD-010 | C11: Standing Desk Frame | D11: Furniture | E11: ComfortSeating | F11: 2026-02-03 | G11: 15 | H11: 15 | I11: 12500 | J11: 4 | K11: Counts match
A12: INV-1011 | B12: PROD-001 | C12: Wireless Mouse | D12: Peripherals | E12: TechGlobal Inc. | F12: 2026-01-10 | G12: 120 | H12: 118 | I12: 450 | J12: 25 | K12: Exact Duplicate of INV-1001
A13: INV-1012 | B13: PROD-011 | C13: HDMI Cable 2m | D13: Accessories | E13: DataLink Corp. | F13: 02/05/2026 | G13: 200 | H13: 195 | I13: 250 | J13: 40 | K13: Discrepancy (-5)
A14: INV-1013 | B14: PROD-012 | C14: Wi-Fi 6 Router | D14: Networking | E14: NetGear Asia | F14: 2026-02-08 | G14: 45 | H14: 45 | I14: 3100 | J14: 10 | K14: Counts match
A15: INV-1014 | B15: PROD-013 | C15: Gaming Headset | D15: Audio | F15: 2026.02-10 | G15: 65 | H15: 60 | I15: 2100 | J15: 15 | K15: Missing supplier, date format issue
A16: INV-1015 | B16: PROD-014 | C16: Portable Power Bank | D16: Power | E16: VoltCorp | F16: 2026-02-12 | G16: 90 | H16: 88 | I16: 1750 | J16: 20 | K16: Discrepancy (-2)
A17: INV-1016 | B17: PROD-015 | C17: RGB Mousepad | D17: Peripherals | E17: TechGlobal Inc. | F17: 02/15/2026 | G17: 110 | H17: 110 | I17: 550 | J17: 25 | K17: Counts match
A18: INV-1017 | B18: PROD-016 | C18: NVMe M.2 2TB | D18: Storage | E18: Apex Electronics | F18: 2026-02-18 | G18: 25 | H18: 22 | I18: 7800 | J18: 8 | K18: Discrepancy (-3)
A19: INV-1018 | B19: PROD-017 | C19: Ethernet Switch 8-Port | D19: Networking | E19: NetGear Asia | F19: 2026-02-20 | G19: 35 | H19: 35 | I19: 1400 | J19: 10 | K19: Counts match
A20: INV-1019 | B20: PROD-018 | C20: USB-C Multi Adapter | D20: Accessories | E20: DataLink Corp. | F20: 02/22/2026 | G20: 80 | H20: 76 | I20: 1100 | J20: 20 | K20: Discrepancy (-4)
A21: INV-1020 | B21: PROD-019 | C21: LED Desk Lamp | D21: Lighting | E21: BrightHome | F21: 2026-02-25 | G21: 55 | H21: 55 | I21: 890 | J21: 12 | K21: Counts match
A22: INV-1021 | B22: PROD-020 | C22: Tablet Stand | D22: Accessories | E22: DataLink Corp. | F22: 2026-02-28 | G22: 70 | H22: 70 | I22: 480 | J22: 15 | K22: Counts match
A23: INV-1022 | B23: PROD-021 | C23: Microphone Boom Arm | D23: Audio | F23: 03/02/2026 | G23: 30 | H23: 28 | I23: 1350 | J23: 8 | K23: Missing supplier
A24: INV-1023 | B24: PROD-022 | C24: Smart Plug Wi-Fi | D24: Smart Home | E24: HomeIoT | F24: 2026-03-05 | G24: 95 | H24: 95 | I24: 620 | J24: 20 | K24: Counts match
A25: INV-1024 | B25: PROD-023 | C25: Security Camera 1080p | D25: Smart Home | E25: HomeIoT | F25: 2026-03-08 | G25: 40 | H25: 39 | I25: 2400 | J25: 10 | K25: Discrepancy (-1)
A26: INV-1025 | B26: PROD-005 | C26: LAPTOP STAND | D26: Accessories | E26: DataLink Corp. | F26: 2026-01-20 | G26: 60 | H26: 55 | I26: 950 | J26: 20 | K26: Exact Duplicate of INV-1005
A27: INV-1026 | B27: PROD-024 | C27: Graphics Drawing Tablet | D27: Peripherals | E27: VisionTech | F27: 03/10/2026 | G27: 18 | H27: 16 | I27: 4900 | J27: 5 | K27: Discrepancy (-2)
A28: INV-1027 | B28: PROD-025 | C28: Bluetooth Earbuds | D28: Audio | E28: SoundWave Ph | F28: 2026-03-12 | G28: 130 | H28: 125 | I28: 1600 | J28: 30 | K28: Discrepancy (-5)
A29: INV-1028 | B29: PROD-026 | C29: Type-C Charging Cable | D29: Accessories | E29: DataLink Corp. | F29: 2026-03-15 | G29: 250 | H29: 245 | I29: 180 | J29: 50 | K29: Discrepancy (-5)
A30: INV-1029 | B30: PROD-027 | C30: Monitor Light Bar | D30: Accessories | E30: BrightHome | F30: 03/18/2026 | G30: 45 | H30: 45 | I30: 1950 | J30: 10 | K30: Counts match
A31: INV-1030 | B31: PROD-028 | C31: Wireless Numeric Keypad | D31: Peripherals | E31: TechGlobal Inc. | F31: 2026-03-20 | G31: 60 | H31: 60 | I31: 750 | J31: 15 | K31: Counts match
A32: INV-1031 | B32: PROD-029 | C32: KVM Switch 2-Port | D32: Networking | F32: 2026-03-22 | G32: 22 | H32: 21 | I32: 2300 | J32: 6 | K32: Missing supplier, discrepancy (-1)
A33: INV-1032 | B33: PROD-030 | C33: Laptop Privacy Screen | D33: Accessories | E33: DataLink Corp. | F33: 03/25/2026 | G33: 50 | H33: 50 | I33: 1250 | J33: 12 | K33: Counts match
A34: INV-1033 | B34: PROD-031 | C34: Vertical Ergonomic Mouse | D34: Peripherals | E34: TechGlobal Inc. | F34: 2026-03-28 | G34: 65 | H34: 62 | I34: 1150 | J34: 15 | K34: Discrepancy (-3)
A35: INV-1034 | B35: PROD-032 | C35: USB Hub 7-Port Powered | D35: Accessories | E35: DataLink Corp. | F35: 2026-03-30 | G35: 40 | H35: 40 | I35: 1450 | J35: 10 | K35: Counts match
A36: INV-1035 | B36: PROD-033 | C36: Mechanical NumPad | D36: Peripherals | E36: TechGlobal Inc. | F36: 04/01/2026 | G36: 35 | H36: 33 | I36: 980 | J36: 10 | K36: Discrepancy (-2)
A37: INV-1036 | B37: PROD-034 | C37: Desk Mat Extended | D37: Accessories | E37: BrightHome | F37: 2026-04-03 | G37: 110 | H37: 110 | I37: 420 | J37: 25 | K37: Counts match
A38: INV-1037 | B38: PROD-035 | C38: Cable Management Box | D38: Accessories | E38: BrightHome | F38: 2026-04-05 | G38: 80 | H38: 78 | I38: 350 | J38: 20 | K38: Discrepancy (-2)
A39: INV-1038 | B39: PROD-003 | C39: 27-inch IPS Monitor | D39: Displays | E39: Apex Electronics | F39: 01/15/2026 | G39: 40 | H39: 38 | I39: 8500 | J39: 10 | K39: Exact Duplicate of INV-1003
A40: INV-1039 | B40: PROD-036 | C40: Webcam Ring Light | D40: Peripherals | E40: VisionTech | F40: 04/08/2026 | G40: 75 | H40: 75 | I40: 850 | J40: 15 | K40: Counts match
...

Sheet Verified Inventory
A1: Record ID | B1: Product ID | C1: Product Name | D1: Category | E1: Supplier | F1: Date Recorded | G1: System Quantity | H1: Physical Count | I1: Variance | J1: Unit Cost (PHP) | K1: Discrepancy Value (PHP) | L1: Reorder Level | M1: Stock Status | N1: Remarks / Cleaning Notes
A2: INV-1001 | B2: PROD-001 | C2: Wireless Mouse | D2: Peripherals | E2: TechGlobal Inc. | F2: 2026-01-10 | G2: 120 | H2: 118 | I2: =H2-G2 | J2: 450 | K2: =ABS(I2)*J2 | L2: 25 | M2: =IF(H2<=L2,"Low Stock",IF(I2<>0,"Discrepancy Flagged","Normal")) | N2: Trimmed spaces, resolved minor stock variance (-2)
A3: INV-1002 | B3: PROD-002 | C3: Mechanical Keyboard | D3: Peripherals | E3: TechGlobal Inc. | F3: 2026-01-12 | G3: 75 | H3: 75 | I3: =H3-G3 | J3: 1850 | K3: =ABS(I3)*J3 | L3: 15 | M3: =IF(H3<=L3,"Low Stock",IF(I3<>0,"Discrepancy Flagged","Normal")) | N3: Standardized name and ID; counts verified
A4: INV-1003 | B4: PROD-003 | C4: 27-inch IPS Monitor | D4: Displays | E4: Apex Electronics | F4: 2026-01-15 | G4: 40 | H4: 38 | I4: =H4-G4 | J4: 8500 | K4: =ABS(I4)*J4 | L4: 10 | M4: =IF(H4<=L4,"Low Stock",IF(I4<>0,"Discrepancy Flagged","Normal")) | N4: Standardized date format; variance (-2) flagged
A5: INV-1004 | B5: PROD-004 | C5: USB-C Hub | D5: Accessories | E5: DataLink Corp. | F5: 2026-01-18 | G5: 150 | H5: 150 | I5: =H5-G5 | J5: 650 | K5: =ABS(I5)*J5 | L5: 30 | M5: =IF(H5<=L5,"Low Stock",IF(I5<>0,"Discrepancy Flagged","Normal")) | N5: Fixed product ID case and trailing spaces
A6: INV-1005 | B6: PROD-005 | C6: Laptop Stand | D6: Accessories | E6: DataLink Corp. | F6: 2026-01-20 | G6: 60 | H6: 55 | I6: =H6-G6 | J6: 950 | K6: =ABS(I6)*J6 | L6: 20 | M6: =IF(H6<=L6,"Low Stock",IF(I6<>0,"Discrepancy Flagged","Normal")) | N6: Fixed capitalization; variance (-5) flagged
A7: INV-1006 | B7: PROD-006 | C7: External SSD 1TB | D7: Storage | E7: [Missing Supplier - Follow-up] | F7: 2026-01-22 | G7: 30 | H7: 30 | I7: =H7-G7 | J7: 4200 | K7: =ABS(I7)*J7 | L7: 10 | M7: =IF(H7<=L7,"Low Stock",IF(I7<>0,"Discrepancy Flagged","Normal")) | N7: Missing supplier flagged; preserved blank per integrity rule
A8: INV-1007 | B8: PROD-007 | C8: HD Webcam 1080p | D8: Peripherals | E8: VisionTech | F8: 2026-01-25 | G8: 85 | H8: 80 | I8: =H8-G8 | J8: 1200 | K8: =ABS(I8)*J8 | L8: 20 | M8: =IF(H8<=L8,"Low Stock",IF(I8<>0,"Discrepancy Flagged","Normal")) | N8: Standardized date format; variance (-5) flagged
A9: INV-1008 | B9: PROD-008 | C9: Bluetooth Speaker | D9: Audio | E9: SoundWave Ph | F9: 2026-01-28 | G9: 50 | H9: 50 | I9: =H9-G9 | J9: 1500 | K9: =ABS(I9)*J9 | L9: 15 | M9: =IF(H9<=L9,"Low Stock",IF(I9<>0,"Discrepancy Flagged","Normal")) | N9: Standardized date format; counts verified
A10: INV-1009 | B10: PROD-009 | C10: Ergonomic Office Chair | D10: Furniture | E10: ComfortSeating | F10: 2026-02-01 | G10: 20 | H10: 18 | I10: =H10-G10 | J10: 5400 | K10: =ABS(I10)*J10 | L10: 5 | M10: =IF(H10<=L10,"Low Stock",IF(I10<>0,"Discrepancy Flagged","Normal")) | N10: Variance (-2) flagged for investigation
A11: INV-1010 | B11: PROD-010 | C11: Standing Desk Frame | D11: Furniture | E11: ComfortSeating | F11: 2026-02-03 | G11: 15 | H11: 15 | I11: =H11-G11 | J11: 12500 | K11: =ABS(I11)*J11 | L11: 4 | M11: =IF(H11<=L11,"Low Stock",IF(I11<>0,"Discrepancy Flagged","Normal")) | N11: Counts match; verified
A12: INV-1012 | B12: PROD-011 | C12: HDMI Cable 2m | D12: Accessories | E12: DataLink Corp. | F12: 2026-02-05 | G12: 200 | H12: 195 | I12: =H12-G12 | J12: 250 | K12: =ABS(I12)*J12 | L12: 40 | M12: =IF(H12<=L12,"Low Stock",IF(I12<>0,"Discrepancy Flagged","Normal")) | N12: Standardized date format; variance (-5) flagged
A13: INV-1013 | B13: PROD-012 | C13: Wi-Fi 6 Router | D13: Networking | E13: NetGear Asia | F13: 2026-02-08 | G13: 45 | H13: 45 | I13: =H13-G13 | J13: 3100 | K13: =ABS(I13)*J13 | L13: 10 | M13: =IF(H13<=L13,"Low Stock",IF(I13<>0,"Discrepancy Flagged","Normal")) | N13: Counts match; verified
... A38: INV-1040 | B38: PROD-037 | C38: Mini PC Mount VESA | D38: Accessories | E38: DataLink Corp. | F38: 2026-04-10 | G38: 30 | H38: 30 | I38: =H38-G38 | J38: 680 | K38: =ABS(I38)*J38 | L38: 8 | M38: =IF(H38<=L38,"Low Stock",IF(I38<>0,"Discrepancy Flagged","Normal")) | N38: Counts match; verified
A39: Total / Summary | G39: =SUM(G2:G38) | H39: =SUM(H2:H38) | I39: =SUM(I2:I38) | K39: =SUM(K2:K38)

Sheet Inventory Audit Log
A1: Record ID | B1: Product ID | C1: Issue Type | D1: Original Value or Issue | E1: Verification Action | F1: Result or Resolution | G1: Follow-up Required
A2: INV-1001 / INV-1011 | B2: PROD-001 | C2: Exact Duplicate Record | D2: Identical record entered twice (INV-1011) | E2: Cross-referenced Record IDs and timestamps | F2: Resolved (Merged/Removed INV-1011) | G2: None
A3: INV-1003 | B3: PROD-003 | C3: Inconsistent Date Format | D3: 01/15/2026 | E3: Standardized date format to YYYY-MM-DD | F3: Resolved | G3: None
A4: INV-1004 | B4: PROD-004 | C4: Formatting / Spacing | D4: prod-004 / 'USB-C Hub ' | E4: Fixed product ID casing and trimmed trailing spaces | F4: Resolved | G4: None
A5: INV-1005 / INV-1025 | B5: PROD-005 | C5: Exact Duplicate Record | D5: Identical record entered twice (INV-1025) | E5: Cross-referenced Record IDs and timestamps | F5: Resolved (Merged/Removed INV-1025) | G5: None
A6: INV-1006 | B6: PROD-006 | C6: Missing Information | D6: Blank supplier field | E6: Checked vendor master files; unverified | F6: Preserved blank; flagged as missing | G6: Contact procurement to verify primary supplier
A7: INV-1007 | B7: PROD-007 | C7: Quantity Discrepancy | D7: System: 85, Physical: 80 (Variance: -5) | E7: Calculated variance and estimated discrepancy PHP value | F7: Flagged for warehouse investigation | G7: Investigate stock movement logs for unrecorded dispatch
A8: INV-1014 | B8: PROD-013 | C8: Missing Info & Date Issue | D8: Blank supplier / '2026.02-10' | E8: Standardized date; flagged blank supplier | F8: Preserved blank supplier; standardized date | G8: Contact procurement to verify supplier
A9: INV-1022 | B9: PROD-021 | C9: Missing Information | D9: Blank supplier field | E9: Checked vendor master files; unverified | F9: Preserved blank; flagged as missing | G9: Contact procurement to verify primary supplier
A10: INV-1025 | B10: PROD-005 | C10: Exact Duplicate Record | D10: Identical record entered twice (INV-1005) | E10: Cross-referenced Record IDs and timestamps | F10: Resolved (Merged/Removed INV-1005) | G10: None
A11: INV-1031 | B11: PROD-029 | C11: Missing Info & Discrepancy | D11: Blank supplier / System: 22, Physical: 21 | E11: Flagged missing supplier and calculated variance (-1) | F11: Flagged for follow-up and investigation | G11: Contact procurement & verify warehouse count
A12: INV-1038 | B12: PROD-003 | C12: Exact Duplicate Record | D12: Identical record entered twice (INV-1003) | E12: Cross-referenced Record IDs and timestamps | F12: Resolved (Merged/Removed INV-1038) | G12: None
